Workbook

Sheet Especificações faciais-H
A1: Especificações Faciais: REV 10 - 22/08/2025 - Juliano
A2: Especificações Técnicas | B2: SpeedFace V5L | C2: SpeedFace M4 | D2: SpeedFace V4L | E2: SpeedFace V4L Pro | F2: SpeedFace V3L Lite | G2: FaceDepot 7BL | H2: ProMA | I2: ProMA-QR | J2: ProMA-RF | K2: Proface X [P] | L2: Proface X [SL] | M2: Proface X [DS] | N2: SenseFace 7A | O2: SenseFace 4A | P2: SenseFace 3A | Q2: SenseFace 2A
A3: Documentos
A4: Status do produto no Brasil | B4: Ativo | C4: Ativo | D4: Phase Out | E4: Roadmap 2025 | F4: Descontinuado | G4: Ativo | H4: Não comercializado | I4: Ativo | J4: Não comercializado | K4: Ativo | L4: Ativo | M4: Ativo | N4: Ativo | O4: Ativo | P4: Ativo | Q4: Ativo
A5: Site China | B5: https://x.gd/WVHGK | C5: https://x.gd/saNe2Y | D5: https://x.gd/nQW3p | E5: https://x.gd/fnC7z | F5: https://x.gd/P36FG | G5: https://x.gd/RsiME | H5: https://x.gd/dUU6Q | I5: https://x.gd/GzN3O | J5: https://x.gd/CyiTH | K5: https://x.gd/dfTkm | L5: https://x.gd/7kv9n | M5: https://x.gd/qhlEE | N5: https://x.gd/k4Zlp | O5: https://x.gd/JYIS6 | P5: https://x.gd/sHSX0 | Q5: https://x.gd/ozfng
A6: Datasheet China | B6: https://x.gd/LexWe | C6: https://x.gd/aWOqN | D6: https://x.gd/pOCoD | E6: https://x.gd/0pOCn | F6: https://x.gd/hr4vD | G6: https://x.gd/3pALb | H6: https://x.gd/hN3J9 | I6: https://x.gd/AxN2g | J6: https://x.gd/lseLK | K6: https://x.gd/yvtVL | L6: https://x.gd/lZ6KH | M6: https://x.gd/NHkVf | N6: https://x.gd/WU2sm | O6: https://x.gd/kGDgP | P6: https://x.gd/aCMMK | Q6: https://x.gd/sa2G4
A7: Guia Rápido China | B7: https://x.gd/Xsi6U | C7: https://x.gd/tPlTS | D7: https://x.gd/7qaCQ | E7: https://x.gd/wRgAe | F7: https://x.gd/oB5oH | G7: https://x.gd/dphkr | H7: https://x.gd/d5M177 | I7: https://x.gd/I6pbP | J7: https://x.gd/c3pAX | K7: https://x.gd/sLOJQ | M7: https://x.gd/SGZhM | N7: https://x.gd/KNYpG | O7: https://x.gd/schbV | P7: https://x.gd/ZDG6o | Q7: https://x.gd/XjsGH
A8: Manual do Usuário China | B8: https://x.gd/UoHyj | C8: https://x.gd/dy6cC | D8: https://x.gd/c4FKA | E8: https://x.gd/HDrro | F8: https://x.gd/r3FYG | G8: https://x.gd/TeNS4 | H8: https://x.gd/f9n6w | I8: https://x.gd/QWTKH | J8: https://x.gd/mseG6 | K8: https://x.gd/l8RJO | M8: https://x.gd/VpgLO | N8: https://x.gd/sNoYY | O8: https://x.gd/r1SY5 | P8: https://x.gd/6BpiK | Q8: https://x.gd/vq9LD
A9: Site BR | B9: https://x.gd/EKVwZ | C9: https://x.gd/jshI5 | G9: https://x.gd/XKAqc | I9: https://x.gd/aPl5G | K9: https://x.gd/iZgpR | L9: https://x.gd/UcXGg | M9: https://x.gd/96yRQ | N9: https://x.gd/OFIDL | O9: https://x.gd/FhhgH | P9: https://x.gd/wK69j | Q9: https://x.gd/nuadW
A10: Datasheet BR | B10: https://x.gd/Fzeni | C10: https://x.gd/xW36Z | D10: https://x.gd/p7WqA | F10: https://x.gd/tzIpx | G10: https://x.gd/N9R41 | I10: https://x.gd/NNLc4 | L10: https://x.gd/7ZECc | M10: https://x.gd/3SJEA | N10: https://x.gd/xPQo7 | O10: https://x.gd/Ub2rS | P10: https://x.gd/GOYYE | Q10: https://x.gd/OgG6B
A11: Guia Rápido BR | B11: https://x.gd/JXKPj | D11: https://x.gd/7EDKM | F11: https://x.gd/oOfK5 | L11: https://x.gd/IWRjf
A12: Manual do Usuário BR | B12: https://x.gd/utTW5 | C12: https://x.gd/81rju | D12: https://x.gd/5S8zc | F12: https://x.gd/3QcwW | G12: https://x.gd/DUIn8 | I12: https://x.gd/RIkCo | K12: https://x.gd/AlM2U | L12: https://x.gd/IgZap | M12: https://x.gd/P9rWl
A13: Desenho DWG | E13: Não tem | G13: Não tem
A14: Caminho servidor ZKBrasil | B14: \\192.168.12.202\Zkteco\Documentos ZKTeco\06. Produtos\1. Controle de acesso de pessoas\1. Biométricos, RFID e QRCode\SpeedFace-V5L [P] - ZAM180 | C14: \\192.168.12.202\Zkteco\Documentos ZKTeco\06. Produtos\1. Controle de acesso de pessoas\1. Biométricos, RFID e QRCode\SpeedFace M4 | D14: \\192.168.12.202\Zkteco\Documentos ZKTeco\06. Produtos\1. Controle de acesso de pessoas\1. Biométricos, RFID e QRCode\SpeedFace V4L - ZAM180 | E14: Z:\Documentos ZKTeco\06. Produtos\1. Controle de acesso de pessoas\1. Biométricos, RFID e QRCode\SpeedFace V4L Pro | F14: \\192.168.12.202\Zkteco\Documentos ZKTeco\06. Produtos\1. Controle de acesso de pessoas\1. Biométricos, RFID e QRCode\SpeedFace V3L (Lite) | G14: \\192.168.12.202\Zkteco\Documentos ZKTeco\06. Produtos\1. Controle de acesso de pessoas\1. Biométricos, RFID e QRCode\Facedepot 7BL | I14: \\192.168.12.202\Zkteco\Documentos ZKTeco\06. Produtos\1. Controle de acesso de pessoas\1. Biométricos, RFID e QRCode\ProMA | K14: \\192.168.12.202\Zkteco\Documentos ZKTeco\06. Produtos\1. Controle de acesso de pessoas\1. Biométricos, RFID e QRCode\ProFace X[P] | L14: \\192.168.12.202\Zkteco\Documentos ZKTeco\06. Produtos\1. Controle de acesso de pessoas\1. Biométricos, RFID e QRCode\Proface X (SL) | M14: Z:\Documentos ZKTeco\06. Produtos\1. Controle de acesso de pessoas\1. Biométricos, RFID e QRCode\ProFace X DS | N14: \\192.168.12.202\Zkteco\Documentos ZKTeco\06. Produtos\1. Controle de acesso de pessoas\1. Biométricos, RFID e QRCode\SenseFace\SenseFace 7A | O14: Z:\Documentos ZKTeco\06. Produtos\1. Controle de acesso de pessoas\1. Biométricos, RFID e QRCode\SenseFace\SenseFace 4A | P14: Z:\Documentos ZKTeco\06. Produtos\1. Controle de acesso de pessoas\1. Biométricos, RFID e QRCode\SenseFace\SenseFace 3A | Q14: Z:\Documentos ZKTeco\06. Produtos\1. Controle de acesso de pessoas\1. Biométricos, RFID e QRCode\SenseFace\SenseFace 2A
A15: Certificados Internacionais (CE, FCC, SGS, IP65…) | B15: Z:\Documentos ZKTeco\06. Produtos\1. Controle de acesso de pessoas\1. Biométricos, RFID e QRCode\SpeedFace-V5L [P] - ZAM180\Certificados | C15: Z:\Documentos ZKTeco\06. Produtos\1. Controle de acesso de pessoas\1. Biométricos, RFID e QRCode\SpeedFace M4\Certificados | D15: Z:\Documentos ZKTeco\06. Produtos\1. Controle de acesso de pessoas\1. Biométricos, RFID e QRCode\SpeedFace-V4L\Certificados | E15: Z:\Documentos ZKTeco\06. Produtos\1. Controle de acesso de pessoas\1. Biométricos, RFID e QRCode\SpeedFace V4L Pro\Certificados | F15: Z:\Documentos ZKTeco\06. Produtos\1. Controle de acesso de pessoas\1. Biométricos, RFID e QRCode\SpeedFace V3L (Lite)\Certificados | G15: Z:\Documentos ZKTeco\06. Produtos\1. Controle de acesso de pessoas\1. Biométricos, RFID e QRCode\Facedepot 7BL\Certificados | H15: \\192.168.12.202\Zkteco\Documentos ZKTeco\06. Produtos\1. Controle de acesso de pessoas\1. Biométricos, RFID e QRCode\ProMA | I15: \\192.168.12.202\Zkteco\Documentos ZKTeco\06. Produtos\1. Controle de acesso de pessoas\1. Biométricos, RFID e QRCode\ProMA | J15: \\192.168.12.202\Zkteco\Documentos ZKTeco\06. Produtos\1. Controle de acesso de pessoas\1. Biométricos, RFID e QRCode\ProMA | K15: Z:\Documentos ZKTeco\06. Produtos\1. Controle de acesso de pessoas\1. Biométricos, RFID e QRCode\ProFace X - ZAM 180\Certificados | L15: Não temos essa informação | M15: Z:\Documentos ZKTeco\06. Produtos\1. Controle de acesso de pessoas\1. Biométricos, RFID e QRCode\ProFace X DS\Certificados | N15: Z:\Documentos ZKTeco\06. Produtos\1. Controle de acesso de pessoas\1. Biométricos, RFID e QRCode\SenseFace\Certificações\Certificações (China) | O15: Z:\Documentos ZKTeco\06. Produtos\1. Controle de acesso de pessoas\1. Biométricos, RFID e QRCode\SenseFace\Certificações\Certificações (China) | P15: Z:\Documentos ZKTeco\06. Produtos\1. Controle de acesso de pessoas\1. Biométricos, RFID e QRCode\SenseFace\Certificações\Certificações (China) | Q15: Z:\Documentos ZKTeco\06. Produtos\1. Controle de acesso de pessoas\1. Biométricos, RFID e QRCode\SenseFace\Certificações\Certificações (China)
A16: Capacidade
A17: Capacidade de Usuários | B17: 10.000 (Opcional: 50.000) | C17: 10.000 (Opcional: 50.000) | D17: 1.000 (Opcional: 2.000) | E17: 10000 | F17: 3.000 (Opcional: 10.000) | G17: 50000 | H17: 30000 | I17: 30000 | J17: 30000 | K17: 50000 | L17: 50000 | M17: 50000 | N17: 10.000 (Opcional: 50.000) | O17: 8000 | P17: 6000 | Q17: 3000
A18: Capacidade de Faces | B18: 10.000 (Opcional: 50.000) | C18: 10.000 (Opcional: 50.000) | D18: 1.000 (Opcional: 2.000) | E18: 6000 | F18: 3000 | G18: 50.000 (Opcional: 100.000) | H18: 30000 | I18: 30.000 (Opcional: 50.000) | J18: N/A | K18: 50.000 (Opcional: 100.000) | L18: 30.000 (Opcional: 50.000) | M18: 30.000 (Opcional: 50.000) | N18: 10.000 (Opcional: 50.000) | O18: 6000 | P18: 4000 | Q18: 3000
A19: Capacidade de Digitais | B19: 10.000 (Opcional: 50.000) | C19: N/A | D19: N/A | E19: 6000 | F19: N/A | G19: Opcional:10.000 | H19: 10000 | I19: N/A | J19: N/A | K19: N/A | L19: N/A | M19: N/A | N19: 10.000 (Opcional: 50.000) | O19: 8000 | P19: 3000 | Q19: 3000
A20: Capacidade de Palma | B20: 3000 | C20: 3000 | D20: 1000 | E20: N/A | F20: N/A | G20: Opcional:3.000 | H20: Opcional: 5.000 | I20: Opcional: 5.000 | J20: Opcional: 5.000 | K20: 5000 | L20: N/A | M20: N/A | N20: N/A | O20: N/A | P20: N/A | Q20: N/A
A21: Capacidade de QR Code | B21: 10.000 (Opcional: 50.000) | C21: 10.000 (Opcional: 50.000) | D21: 1.000 (Opcional: 2.000) | E21: N/A | F21: N/A | G21: N/A | H21: N/A | I21: 100000 | J21: Opcional: 5.000 | K21: 50000 | L21: N/A | M21: 50000 | N21: N/A | O21: N/A | P21: N/A | Q21: N/A
A22: Capacidade de Cartões RFID | B22: 10.000 (Opcional: 50.000) | C22: 10.000 (Opcional: 50.000) | D22: 1.000 (Opcional: 2.000) | E22: 10000 | F22: 3.000 (Opcional: 10.000) | G22: Opcional:10.000 | H22: N/A | I22: N/A | J22: 100000 | K22: 50000 | L22: 50000 | M22: 50000 | N22: Em breve | O22: Em breve | P22: 6000 | Q22: N/A
A23: Capacidade de Senhas | B23: 10.000 (Opcional: 50.000) | C23: 10.000 (Opcional: 50.000) | D23: 1.000 (Opcional: 2.000) | E23: 10000 | F23: 3.000 (Opcional: 10.000) | G23: 50000 | H23: 30000 | I23: 30000 | K23: 50000 | L23: 50000 | M23: 50000 | N23: 10.000 (Opcional: 50.000) | O23: 8000 | P23: 6000 | Q23: 3000
A24: Quantidade de Administradores | B24: 10.000 (Opcional: 50.000) | C24: 10.000 (Opcional: 50.000) | D24: 1.000 (Opcional: 2.000) | E24: 10000 | F24: 3.000 (Opcional: 10.000) | G24: 50000 | H24: 30000 | I24: 30000 | K24: 50000 | L24: 50000 | M24: 50000 | N24: 10.000 (Opcional: 50.000) | O24: 8000 | P24: 6000 | Q24: 3000
A25: Capacidade de Registros | B25: 200000 | C25: 200.000 (Opcional 500.000) | D25: 150000 | E25: 200000 | F25: 200000 | G25: 200000 | H25: 500000 | I25: 500000 | J25: 500000 | K25: 1.000.000 (Opcional: 2.000.000) | L25: 1.000.000 (Opcional: 2.000.000) | M25: 1.000.000 (Opcional: 2.000.000) | N25: 300000 | O25: 200000 | P25: 150000 | Q25: 150000
A26: Especificações Técnicas Gerais
A27: Código Sankhya
A28: NCM | B28: 85437099 | C28: 85437099 | D28: 85437099 | E28: 85437099 | F28: 85437099 | G28: 85437099 | H28: 85437099 | I28: 85437099 | J28: 85437099 | K28: 85437099 | L28: 85437099 | M28: 85437099 | N28: 85437099 | O28: 85437099 | P28: 85437099 | Q28: 85437099
A29: Base de Dados Local | B29: Sim | C29: Sim | D29: Sim | E29: Sim | F29: Sim | G29: Sim | H29: Sim | I29: Sim | J29: Sim | K29: Sim | L29: Sim | M29: Sim | N29: Sim | O29: Sim | P29: Sim | Q29: Sim
A30: Conexão Ethernet | B30: TCP/IP (10/100Base-T) | C30: TCP/IP (10/100Base-T) | D30: TCP/IP (10/100Base-T) | E30: TCP/IP (10/100Base-T) | F30: TCP/IP (10/100Base-T) | G30: TCP/IP (10/100Base-T) | H30: TCP/IP (10/100Base-T) | I30: TCP/IP (10/100Base-T) | J30: TCP/IP (10/100Base-T) | K30: TCP/IP (10/100Base-T) | L30: TCP/IP (10/100Base-T) | M30: TCP/IP (10/100Base-T) | N30: TCP/IP (10/100Base-T) | O30: TCP/IP (10/100Base-T) | P30: TCP/IP (10/100Base-T) | Q30: TCP/IP (10/100Base-T)
A31: Acompanha fonte de alimentação? | B31: sim | C31: sim | D31: sim | E31: sim | F31: sim | G31: sim | H31: sim | I31: sim | J31: sim | K31: sim | L31: sim | M31: sim | N31: Não | O31: Não | P31: Não | Q31: Não
A32: Tensão de Alimentação | B32: 12Vcc | C32: 12Vcc | D32: 12Vcc | E32: 12Vcc | F32: 12Vcc | G32: 12Vcc | H32: 12Vcc | I32: 12Vcc | J32: 12Vcc | K32: 12Vcc | L32: 12Vcc | M32: 12Vcc | N32: 12Vcc | O32: 12Vcc | P32: 12Vcc | Q32: 12Vcc
A33: Corrente | B33: 3A | C33: 3A | D33: 3A | E33: 3A | F33: 1.5A | G33: 3A | H33: 3A | I33: 3A | J33: 3A | K33: 3A | L33: 3A | M33: 3A | N33: 3A | O33: 3A | P33: 3A | Q33: 3A
A34: Tecnologia RFID | B34: ID 125Khz ou 13,56Mhz | C34: ID 125Khz ou 13,56Mhz | D34: ID 125Khz ou 13,56Mhz | E34: ID 125Khz ou 13,56Mhz | F34: ID 125Khz ou 13,56Mhz | G34: ID 125Khz ou 13,56Mhz | H34: ID 125Khz ou 13,56Mhz | I34: ID 125Khz ou 13,56Mhz | J34: ID 125Khz ou 13,56Mhz | K34: ID 125Khz ou 13,56Mhz | L34: 13,56Mhz | M34: ID 125Khz ou 13,56Mhz | N34: 13,56Mhz | O34: N/A | P34: 13,56Mhz | Q34: N/A
A35: Dimensões (L × A × P) | B35: 91,93 x 202,93 x 21,5 (mm) | C35: 103,83 x 212,41 x 50,60 (mm) | D35: 157,94 x 72,94 x 23 (mm) | E35: 183 x 88 x 20,5 (mm) | F35: 116,8 x 8,3 x 17,0 (mm) | G35: 91,93 x 202,93 x 21,5mm | H35: 68,7 x 194,7 x 28,3mm | I35: 68,7 x 194,7 x 28,3mm | J35: 68,7 x 194,7 x 28,3mm | K35: 227 x 143 x 26 mm | L35: 227 x 143 x 26 mm | M35: 227 x 143 x 26 mm | N35: 238 x 115 x 22,3mm | O35: 175.00 x 84.50 x 21.65 mm | P35: 166 x 63 x 25 mm | Q35: 205.20 x 74.19 x 33.30 mm
A36: Consumo Máximo | B36: 36W | C36: 36W | D36: 36W | E36: 36W | F36: 18W | G36: 36W | H36: 36W | I36: 36W | J36: 36W | K36: 36W | L36: 36W | M36: 36W | N36: 36W | O36: 36W | P36: 36W | Q36: 36W
A38: Temperatura de Operação | B38: -10°C a 45°C | C38: -10°C a 50°C | D38: 0°C a 45°C | E38: -5°C a 45°C | F38: -5°C a 45°C | G38: 0°C a 45 °C | H38: -26°C a 55 °C | I38: -26°C a 55 °C | J38: -26°C a 55 °C | K38: -30°C a 60°C | L38: -30°C a 60°C | M38: -20°C a 55°C | N38: -5°C a 45°C | O38: -5°C a 45°C | P38: -5°C a 45°C | Q38: -5°C a 45°C
A39: Umidade Relativa de Operação | B39: 10% a 90% | C39: 10% a 90% | D39: 10% a 90% | E39: 10% a 90% | F39: 10% a 90% | G39: 20% a 80% | H39: ≤ 93% | I39: ≤ 93% | J39: ≤ 93% | K39: ≤ 93% | L39: ≤ 93% | M39: ≤ 93% | N39: 10% a 90% | O39: 10% a 90% | P39: 10% a 90% | Q39: 20% to 80%
A40: Grau de Proteção | B40: N/A | C40: IP66 | D40: N/A | E40: IP65 | F40: IP65 | G40: Opicional: IP65 (Apenas no FaceDepot 7BL-WP) | H40: IP66 | I40: IP66 | J40: IP66 | K40: IP68 | L40: IP68 | M40: IP68 | N40: IP65 | O40: IP65 | P40: IP65 | Q40: N/A
A41: Antivandalismo | B41: N/A | C41: N/A | D41: N/A | E41: N/A | F41: N/A | G41: N/A | H41: IK07 | I41: IK07 | J41: IK07 | K41: IK04 (Opcional: IK10) | L41: IK04 | M41: IK04 | N41: N/A | O41: N/A | P41: N/A | Q41: N/A
...

Sheet Datasheet
A1: Selecione o modelo
A3: ='Especificações faciais-H'!A17 -> Capacidade de Usuários
A4: ='Especificações faciais-H'!A18 -> Capacidade de Faces
A5: ='Especificações faciais-H'!A19 -> Capacidade de Digitais
A6: ='Especificações faciais-H'!A20 -> Capacidade de Palma
A7: ='Especificações faciais-H'!A21 -> Capacidade de QR Code
A8: ='Especificações faciais-H'!A22 -> Capacidade de Cartões RFID
A9: ='Especificações faciais-H'!A23 -> Capacidade de Senhas
A10: ='Especificações faciais-H'!A24 -> Quantidade de Administradores
A11: ='Especificações faciais-H'!A25 -> Capacidade de Registros

Sheet Z-ID
A1: Nome do Modelo | B1: Z-ID mesmo usado no ZK9500
A2: Tipo de Scanner | B2: Óptico
A3: CPU | B3: 280MHz DSP
A4: Flash | B4: 32 MB
A5: SoC | B5: RTOS
A6: Qualidade da Imagem | B6: 2-megapixel CMOS
A7: Dados Criptografados de Impressão Digital | B7: Sim
A8: À Prova de Respingos de Água | B8: Sim
A9: Consumo de Energia | B9: 5V:200mA varredura; 5V:60mA inativo (aguardando o dedo)
A10: LED | B10: Branco
A11: Certificações do Produto | B11: FCC, CE, RoHS
A12: Tensão de Energia | B12: 5V
... A21: Formatos de Imagem | B21: RAW, BMP, JPG
A22: Escala de Cinza | B22: 256
A23: Ambiente Operacional | B23: -20 °C ~ +50 °C; 90% r.h.
A24: Algoritmo | B24: ZKFinger V10.0

Sheet Validação

Sheet Especificações faciais-V
A1: 1 | B1: 2 | C1: 3 | D1: 4 | E1: 5 | F1: 6 | G1: 7 | H1: 8 | I1: 9 | J1: 10 | K1: 11 | L1: 12 | M1: 13 | N1: 14 | O1: 15 | P1: 16 | Q1: 17 | R1: 18 | S1: 19 | T1: 20 | U1: 21 | V1: 22 | W1: 23 | X1: 24 | Y1: 25 | Z1: 26 | AA1: 27 | AB1: 28 | AC1: 29 | AD1: 30 | AE1: 31 | AF1: 32 | AG1: 33 | AH1: 34 | AI1: 35 | AJ1: 36 | AK1: 37 | AL1: 38 | AM1: 39 | AN1: 40 | AO1: 41 | AP1: 42 | AQ1: 43 | AR1: 44 | AS1: 45 | AT1: 46 | AU1: 47 | AV1: 48 | AW1: 49 | AX1: 50 | AY1: 51 | AZ1: 52 | BA1: 53 | BB1: 54 | BC1: 55 | BD1: 56 | BE1: 57 | BF1: 58 | BG1: 59 | BH1: 60 | BI1: 61 | BJ1: 62 | BK1: 63 | BL1: 64 | BM1: 65 | BN1: 66 | BO1: 67 | BP1: 68 | BQ1: 69 | BR1: 70 | BS1: 71 | BT1: 72 | BU1: 73 | BV1: 74 | BW1: 75 | BX1: 76 | BY1: 77 | BZ1: 78 | CA1: 79 | CB1: 80 | CC1: 81 | CD1: 82 | CE1: 83 | CF1: 84 | CG1: 85 | CH1: 86 | CI1: 87 | CJ1: 88 | CK1: 89 | CL1: 90 | CM1: 91 | CN1: 92 | CO1: 93 | CP1: 94 | CQ1: 95 | CR1: 96 | CS1: 97 | CT1: 98 | CU1: 99 | CV1: 100 | CW1: 101 | CX1: 102 | CY1: 103 | CZ1: 104 | DA1: 105 | DB1: 106 | DC1: 107 | DD1: 108 | DE1: 109 | DF1: 110 | DG1: 111 | DH1: 112 | DI1: 113 | DJ1: 114 | DK1: 115 | DL1: 116 | DM1: 117
A2: Especificações Técnicas | B2: Status do produto no Brasil | C2: Site China | D2: Datasheet China | E2: Guia Rápido China | F2: Manual do Usuário China | G2: Site BR | H2: Datasheet BR | I2: Guia Rápido BR | J2: Manual do Usuário BR | K2: Desenho DWG | L2: Caminho servidor ZKBrasil | M2: Certificados Internacionais (CE, FCC, SGS, IP65…) | N2: Capacidade de Usuários | O2: Capacidade de Faces | P2: Capacidade de Digitais | Q2: Capacidade de Palma | R2: Capacidade de QR Code | S2: Capacidade de Cartões RFID | T2: Capacidade de Senhas | U2: Quantidade de Administradores | V2: Capacidade de Registros | W2: Código Sankhya | X2: NCM | Y2: Base de Dados Local | Z2: Conexão Ethernet | AA2: Acompanha fonte de alimentação? | AB2: Tensão de Alimentação | AC2: Corrente | AD2: Tecnologia RFID | AE2: Dimensões (L × A × P) | AF2: Consumo Máximo | AG2: Temperatura de Operação | AH2: Umidade Relativa de Operação | AI2: Grau de Proteção | AJ2: Antivandalismo | AK2: Peso Bruto (KG) | AL2: Ambiente de Instalação | AM2: Certificações internacionais | AN2: Itens da embalagem | AO2: Plataforma | AP2: Versão de firmware | AQ2: CPU | AR2: Sistema Operacional | AS2: Memória RAM | AT2: Memória ROM/Flash | AU2: Display | AV2: Tipo de Tela | AW2: Resolução da tela | AX2: Câmeras | AY2: Compensação de Luz | AZ2: Alto falante | BA2: Microfone | BB2: Tipo de sensor de impressão digital | BC2: Especificações do sensor FP | BD2: WDR | BE2: Sinalização ao Usuário | BF2: Rede TCP/IP | BG2: PoE | BH2: Wi-Fi | BI2: Softwares compatíveis | BJ2: Protocolo Rede | BK2: Protocolo Wiegand | BL2: Protocolo OSDP | BM2: Protocolo SIP | BN2: Protocolo ONVIF | BO2: Protocolo RTSP | BP2: Protcolo HTTPS | BQ2: Tecnologia facial | BR2: Algoritmo de Reconhecimento | BS2: Sensibilidade a lux (LUX) | BT2: Face (Área de exposição) | BU2: Palma AE (Área de exposição) | BV2: Distância de reconhecimento facial | BW2: Índice de Falsa Aceitação (FAR) facial | BX2: Índice de Falsa Rejeição (FRR) facial | BY2: Tempo de Reconhecimento Facial | BZ2: Intervalo de Reconhecimento Facial | CA2: Índice de Falsa Aceitação (FAR) digital | CB2: Índice de Falsa Rejeição (FRR) digital | CC2: Tempo de Reconhecimento digital | CD2: Distância de reconhecimento de palma | CE2: Índice de Falsa Aceitação (FAR) Palma | CF2: Índice de Falsa Rejeição (FRR) Palma | CG2: Tempo de Reconhecimento Palma | CH2: Possibilita confirmação de Passagem com catracas (Entrada Aux ou SEN) | CI2: Reset do equipamento | CJ2: Modo de Autenticação | CK2: Método de Autenticação | CL2: Leitor de Cartão Periférico | CM2: Monitoramento em Tempo Real | CN2: Web Browser | CO2: Configuração da Rede | CP2: Verificação Online | CQ2: Sensor de Movimento | CR2: Sistema de Coação | CS2: Sistema Antifraude ( Anti-Passback) | CT2: Entrada de Alarme | CU2: Saida de Alarme | CV2: Tamper | CW2: Áudio Bidirecional | CX2: Sistema Antifraude (Anti-Fake) | CY2: Integração | CZ2: RS-485 | DA2: RS-232 | DB2: Saída 12Vcc | DC2: Bell (Campainha) | DD2: Wiegand | DE2: USB | DF2: Rede TCP/IP | DG2: Entrada de Alarme | DH2: Saída de alarme | DI2: Botão de saída | DJ2: Detecção do status da porta | DK2: Controle de Porta (Relé) | DL2: Certificações internacionais | DM2: OSDP
A3: SpeedFace V5L | B3: Ativo | C3: https://x.gd/WVHGK | D3: https://x.gd/LexWe | E3: https://x.gd/Xsi6U | F3: https://x.gd/UoHyj | G3: https://x.gd/EKVwZ | H3: https://x.gd/Fzeni | I3: https://x.gd/JXKPj | J3: https://x.gd/utTW5 | L3: \\192.168.12.202\Zkteco\Documentos ZKTeco\06. Produtos\1. Controle de acesso de pessoas\1. Biométricos, RFID e QRCode\SpeedFace-V5L [P] - ZAM180 | M3: Z:\Documentos ZKTeco\06. Produtos\1. Controle de acesso de pessoas\1. Biométricos, RFID e QRCode\SpeedFace-V5L [P] - ZAM180\Certificados | N3: 10.000 (Opcional: 50.000) | O3: 10.000 (Opcional: 50.000) | P3: 10.000 (Opcional: 50.000) | Q3: 3000 | R3: 10.000 (Opcional: 50.000) | S3: 10.000 (Opcional: 50.000) | T3: 10.000 (Opcional: 50.000) | U3: 10.000 (Opcional: 50.000) | V3: 200000 | X3: 85437099 | Y3: Sim | Z3: TCP/IP (10/100Base-T) | AA3: sim | AB3: 12Vcc | AC3: 3A | AD3: ID 125Khz ou 13,56Mhz | AE3: 91,93 x 202,93 x 21,5 (mm) | AF3: 36W | AG3: -10°C a 45°C | AH3: 10% a 90% | AI3: N/A | AJ3: N/A | AK3: 1.3 | AL3: Interno | AM3: ISO14001, ISO9001, CE, FCC | AN3: 1. Equipamento montado. 2. Adesivo de posição de montagem e placa de montagem. 3. Guia rápido. 4. Cabo de alimentação de 12 V/cabo RS232, RS485 /cabo RJ 45/cabo Wiegand/cabo de porta e sensor,etc. 5. Chave torx e parafusos de instalação. 6. Fonte de alimentação de 12V 3A. 7. Diodo FR107. | AO3: ZAM180 | AP3: ZAM180-NF50VA-Ver.4.1.4 | AQ3: 1 GHz Dual Core | AR3: Linux embarcado | AS3: 1GB | AT3: 8GB | AU3: 5 Polegadas | AV3: Tela LCD IPS sensível ao toque | AW3: 720x1080 | AX3: Câmera 2MP Low Litght (WDR) | AY3: Autocompensação de LEDs IR e LEDs brancos. | AZ3: XDEC-2415B08J20NF26-D100 8Ω¸ 1W 24mm*15mm*5mm(1E-2P-100-1.25 32AWG ) RoHS | BA3: XDEC-EM4015 -32dB -32dB±3dB 2.2KΩ φ4.0mm*1.5mm | BB3: Sensor óptico ZK | BC3: Z-ID | BD3: (81 dB linear mode 105 dB HDR mode) | BE3: Sonora (voz) e visual | BF3: 10/100Base-T | BG3: N/A | BH3: IEEE 802.11b / g / n 2.4GHz Wi-Fi 2,4 GHz ~ 2,4835 GHz Suporta 20 MHz e 40 MHz 64/128 bits WEP, WPA/WPA2, WPA-PSK/WPA2-PSK 802.11b: até 11 Mbps, 802.11g: até 54 Mbps, 802.11n: até 300 Mbps (HT40) | BI3: ZKBioCV Access e ZKBioCVSecurity | BJ3: TCP/IP | BK3: Sim | BL3: N/A | BM3: Público (Proprietário) e Privado | BN3: Sim (Profile S???? | BO3: Sim | BP3: Sim | BQ3: Luz visível | BR3: Algoritmo de inteligência artificial (IA) e reconhecimento facial vivo (liveness detection) para prevenir fraudes com fotos ou vídeos. | BS3: 3000 | BT3: Sim | BU3: Sim | BV3: 30cm a 200cm | BW3: ≤ 0.01% | BX3: ≤ 0.02% | BY3: <1s | BZ3: De 0 a 9 segundos | CA3: ≤ 0.0001% | CB3: ≤ 0.01% | CC3: <0.3s | CD3: 30 a 50cm | CE3: ≤ 0.05% | CF3: ≤ 1.8% | CG3: <0.35s | CH3: Sim | CI3: Tamper | CJ3: Face/Palma/Digital/Cartão/QR Code/Senha | CK3: Simples ou combinado | CL3: Wiegand ou RS-485 | CM3: Sim | CN3: Sim | CO3: Sim | CP3: Sim | CQ3: Sim | CR3: Impressão digital ou senha | CS3: Local (Wigand) e Global (Online) | CT3: Sim | CU3: Sim | CV3: Sim | CW3: Sim | CX3: Sim | CY3: PUSH SDK ou API BEST | CZ3: 1 | DA3: 2 | DB3: 1 | DC3: N/A | DD3: 2 (uma para entrada e outra pra saída) | DE3: N/A | DF3: 1 | DG3: 1 | DH3: 1 | DI3: 1 | DJ3: 1 | DK3: 1
A4: SpeedFace M4 | B4: Ativo | C4: https://x.gd/saNe2Y | D4: https://x.gd/aWOqN | E4: https://x.gd/tPlTS | F4: https://x.gd/dy6cC | G4: https://x.gd/jshI5 | H4: https://x.gd/xW36Z | J4: https://x.gd/81rju | L4: \\192.168.12.202\Zkteco\Documentos ZKTeco\06. Produtos\1. Controle de acesso de pessoas\1. Biométricos, RFID e QRCode\SpeedFace M4 | M4: Z:\Documentos ZKTeco\06. Produtos\1. Controle de acesso de pessoas\1. Biométricos, RFID e QRCode\SpeedFace M4\Certificados | N4: 10.000 (Opcional: 50.000) | O4: 10.000 (Opcional: 50.000) | P4: N/A | Q4: 3000 | R4: 10.000 (Opcional: 50.000) | S4: 10.000 (Opcional: 50.000) | T4: 10.000 (Opcional: 50.000) | U4: 10.000 (Opcional: 50.000) | V4: 200.000 (Opcional 500.000) | X4: 85437099 | Y4: Sim | Z4: TCP/IP (10/100Base-T) | AA4: sim | AB4: 12Vcc | AC4: 3A | AD4: ID 125Khz ou 13,56Mhz | AE4: 103,83 x 212,41 x 50,60 (mm) | AF4: 36W | AG4: -10°C a 50°C | AH4: 10% a 90% | AI4: IP66 | AJ4: N/A | AK4: 1.5 | AL4: Interno e externo | AM4: ISO14001, ISO9001, CE, FCC, Anatel | AN4: 1. Equipamento montado. 2. Adesivo de posição de montagem e placa de montagem. 3. Guia rápido. 4. Fonte de alimentação de 12V 3A. 5. Chave torx e parafusos de instalação. 6. Diodo FR107. | AO4: ZAM180 | AP4: ZAM180-NF50VA-Ver.4.1.4 | AQ4: 1 GHz Dual Core | AR4: Linux embarcado | AS4: 1GB | AT4: 8GB | AU4: 5 Polegadas | AV4: Tela LCD IPS sensível ao toque | AW4: 720x1080 | AX4: Câmera 2MP Low Litght (WDR) | AY4: Autocompensação de LEDs IR e LEDs brancos. | AZ4: XDEC-20M08J20NI19-D90 8Ω1.5W φ20*5.5mm (1E-2P-90-2.0-PH 28AWG)·IP67 RoHS | BA4: XDEC-EM4015 Sensitivity-32dB-D90 -32dB±3dB 2.2KΩ φ4.0mm*1.5mm | BB4: N/A | BC4: N/A | BD4: (81 dB linear mode 105 dB HDR mode) | BE4: Sonora (voz) e visual | BF4: 10/100Base-T | BG4: Opcional (interno) IEEE???? | BH4: IEEE 802.11b / g / n 2.4GHz Wi-Fi 2,4 GHz ~ 2,4835 GHz Suporta 20 MHz e 40 MHz 64/128 bits WEP, WPA/WPA2, WPA-PSK/WPA2-PSK 802.11b: até 11 Mbps, 802.11g: até 54 Mbps, 802.11n: até 300 Mbps (HT40) | BI4: ZKBioCV Access e ZKBioCVSecurity | BJ4: TCP/IP | BK4: Sim | BL4: N/A | BM4: Público (Proprietário) e Privado | BN4: Sim (Profile S???? | BO4: Sim | BP4: Sim | BQ4: Luz visível | BR4: Algoritmo de inteligência artificial (IA) e reconhecimento facial vivo (liveness detection) para prevenir fraudes com fotos ou vídeos. | BS4: 30000 | BT4: Sim | BU4: Sim | BV4: 30cm a 200cm | BW4: ≤ 0.01% | BX4: ≤ 0.02% | BY4: ≤0,5s | BZ4: De 0 a 9 segundos | CA4: N/A | CB4: N/A | CC4: N/A | CD4: 30 a 50cm | CE4: ≤ 0.05% | CF4: ≤ 1.8% | CG4: <0.35s | CH4: Sim | CI4: Tamper | CJ4: Face/Palma/Cartão/QR Code/Senha | CK4: Simples ou combinado | CL4: Wiegand ou RS-485 | CM4: Sim | CN4: Sim | CO4: Sim | CP4: Sim | CQ4: Sim | CR4: Senha | CS4: Local (Wigand) e Global (Online) | CT4: Sim | CU4: Sim | CV4: Sim | CW4: Sim | CX4: Sim | CY4: PUSH SDK ou API BEST | CZ4: 1 | DA4: 1 | DB4: 3 | DC4: N/A | DD4: 2 (uma para entrada e outra pra saída) | DE4: N/A | DF4: 1 | DG4: 1 | DH4: 1 | DI4: 1 | DJ4: 1 | DK4: 1
A5: SpeedFace V4L | B5: Phase Out | C5: https://x.gd/nQW3p | D5: https://x.gd/pOCoD | E5: https://x.gd/7qaCQ | F5: https://x.gd/c4FKA | H5: https://x.gd/p7WqA | I5: https://x.gd/7EDKM | J5: https://x.gd/5S8zc | L5: \\192.168.12.202\Zkteco\Documentos ZKTeco\06. Produtos\1. Controle de acesso de pessoas\1. Biométricos, RFID e QRCode\SpeedFace V4L - ZAM180 | M5: Z:\Documentos ZKTeco\06. Produtos\1. Controle de acesso de pessoas\1. Biométricos, RFID e QRCode\SpeedFace-V4L\Certificados | N5: 1.000 (Opcional: 2.000) | O5: 1.000 (Opcional: 2.000) | P5: N/A | Q5: 1000 | R5: 1.000 (Opcional: 2.000) | S5: 1.000 (Opcional: 2.000) | T5: 1.000 (Opcional: 2.000) | U5: 1.000 (Opcional: 2.000) | V5: 150000 | X5: 85437099 | Y5: Sim | Z5: TCP/IP (10/100Base-T) | AA5: sim | AB5: 12Vcc | AC5: 3A | AD5: ID 125Khz ou 13,56Mhz | AE5: 157,94 x 72,94 x 23 (mm) | AF5: 36W | AG5: 0°C a 45°C | AH5: 10% a 90% | AI5: N/A | AJ5: N/A | AK5: 0.85 | AL5: Interno | AM5: ISO14001, ISO9001, CE, FCC | AN5: 1. Equipamento montado. 2. Adesivo de posição de montagem e placa de montagem. 3. Guia rápido. 4. Cabo de alimentação de 12 V/cabo RS232, RS485 /cabo RJ 45/cabo Wiegand/cabo de porta e sensor, etc. 5. Chave torx e parafusos de instalação. 6. Fonte de alimentação de 12V 3A. 7. Diodo FR107. | AO5: ZAM180 | AP5: ZAM180-NF40VA-Ver4.0.9 | AQ5: 900 MHz Dual Core | AR5: Linux embarcado | AS5: 1GB | AT5: 512 MB | AU5: 4 Polegadas | AV5: Tela LCD IPS sensível ao toque | AW5: 480x800 | AX5: Camera Binocular 2MP | AY5: Autocompensação de LEDs IR e LEDs brancos. | AZ5: DS20LA008010J-R-06 8Ω¸ 0.8W φ20*4.5mm(1E-2P-60-1.25 28AWG) | BA5: XDEC-EM4015 -32dB-D40 Sensitivity -32dB±3dB 2.2KΩ,φ4.0mm*1.5mm (1E-2P-40-1.25,40mm±5mm) RoHS | BB5: N/A | BC5: N/A | BD5: 81 dB linear mode | BE5: Sonora (voz) e visual | BF5: 10/100Base-T | BG5: N/A | BH5: IEEE 802.11b / g / n 2.4GHz Wi-Fi 2,4 GHz ~ 2,4835 GHz Suporta 20 MHz e 40 MHz 64/128 bits WEP, WPA/WPA2, WPA-PSK/WPA2-PSK 802.11b: até 11 Mbps, 802.11g: até 54 Mbps, 802.11n: até 300 Mbps (HT40) | BI5: ZKBioCV Access e ZKBioCVSecurity | BJ5: TCP/IP | BK5: Sim | BL5: N/A | BM5: Privado (ZKBioCVSecurity ou ZKBioTalk) | BN5: N/A | BO5: N/A | BP5: Sim | BQ5: Luz visível | BR5: Algoritmo de inteligência artificial (IA) e reconhecimento facial vivo (liveness detection) para prevenir fraudes com fotos ou vídeos. | BS5: 3000 | BT5: N/A | BU5: N/A | BV5: 30cm a 200cm | BW5: ≤ 0.01% | BX5: ≤ 0.02% | BY5: <1s | BZ5: De 0 a 9 segundos | CA5: N/A | CB5: N/A | CC5: N/A | CD5: 30 a 50cm | CE5: ≤ 0.05% | CF5: ≤ 1.8% | CG5: <0.35s | CH5: Sim | CI5: Tamper | CJ5: Face/Palma/Cartão/QR Code/Senha | CK5: Simples ou combinado | CL5: Wiegand ou RS-485 | CM5: Sim | CN5: Sim | CO5: Sim | CP5: Sim | CQ5: Sim | CR5: Senha | CS5: Local (Wigand) e Global (Online) | CT5: Sim | CU5: Sim | CV5: Sim | CW5: Sim | CX5: Sim | CY5: PUSH SDK | CZ5: 1 | DA5: N/A | DB5: 1 | DC5: 1 | DD5: 2 (uma para entrada e outra pra saída) | DE5: 1 | DF5: 1 | DG5: 1 | DH5: 1 | DI5: 1 | DJ5: 1 | DK5: 1
A6: SpeedFace V4L Pro | B6: Roadmap 2025 | C6: https://x.gd/fnC7z | D6: https://x.gd/0pOCn | E6: https://x.gd/wRgAe | F6: https://x.gd/HDrro | K6: Não tem | L6: Z:\Documentos ZKTeco\06. Produtos\1. Controle de acesso de pessoas\1. Biométricos, RFID e QRCode\SpeedFace V4L Pro | M6: Z:\Documentos ZKTeco\06. Produtos\1. Controle de acesso de pessoas\1. Biométricos, RFID e QRCode\SpeedFace V4L Pro\Certificados | N6: 10000 | O6: 6000 | P6: 6000 | Q6: N/A | R6: N/A | S6: 10000 | T6: 10000 | U6: 10000 | V6: 200000 | X6: 85437099 | Y6: Sim | Z6: TCP/IP (10/100Base-T) | AA6: sim | AB6: 12Vcc | AC6: 3A | AD6: ID 125Khz ou 13,56Mhz | AE6: 183 x 88 x 20,5 (mm) | AF6: 36W | AG6: -5°C a 45°C | AH6: 10% a 90% | AI6: IP65 | AJ6: N/A | AK6: 0.503 | AL6: Interno e externo | AM6: ISO14001, ISO9001, CE, FCC, RoHS | AN6: 1. Equipamento montado. 2. Adesivo de posição de montagem e placa de montagem. 3. Guia rápido. 4. Cabo de alimentação de 12 V/cabo RS232, RS485 /cabo RJ 45/cabo Wiegand/cabo de porta e sensor, etc. 5. Chave torx e parafusos de instalação. 6. Alimentação de 12V 3A. 7. Diodo FR107. | AO6: ZAM180 | AP6: ZAM180-NF40VB-Ver4.0.9 | AQ6: 1 GHz Dual Core | AR6: Linux embarcado | AS6: 1GB | AT6: 8GB | AU6: 4 Polegadas | AV6: Tela LED de toque colorida TFT | AW6: 480*800 | AX6: Camera Binocular 2MP | AY6: Autocompensação de LEDs IR | AZ6: ZQ102 speaker ZTX-230107-BOX(1E-2P-65-1.0 30AWG ),8Ω,1W,47.35×12.8×5.65mm,RoHS | BA6: (Sensitivity: -32dB / Omni-directional / Signal-to-Noise Ratio: 58dB / Impedance: 2.2kΩ) | BB6: Sensor óptico ZK | BC6: Z-ID | BD6: (81 dB linear mode 105 dB HDR mode) | BE6: Sonora (voz) e visual | BF6: 10/100Base-T | BG6: N/A | BH6: IEEE 802.11b / g / n 2.4GHz Wi-Fi 2,4 GHz ~ 2,4835 GHz Suporta 20 MHz e 40 MHz 64/128 bits WEP, WPA/WPA2, WPA-PSK/WPA2-PSK 802.11b: até 11 Mbps, 802.11g: até 54 Mbps, 802.11n: até 300 Mbps (HT40) | BI6: ZKBioCV Access e ZKBioCVSecurity | BJ6: TCP/IP | BK6: Sim | BL6: N/A | BM6: Privado (ZKBioCVSecurity ou ZKBioTalk) | BN6: Sim (Profile S???? | BO6: Sim | BP6: Sim | BQ6: Luz visível | BR6: Algoritmo de inteligência artificial (IA) e reconhecimento facial vivo (liveness detection) para prevenir fraudes com fotos ou vídeos. | BS6: 3000 | BT6: N/A | BU6: N/A | BV6: 30cm a 170cm | BW6: ≤0.01% | BX6: ≤0.02% | BY6: <0,35 s | BZ6: De 0 a 9 segundos | CA6: ≤0.0001% | CB6: ≤0.01% | CC6: <0.5s | CD6: N/A | CE6: N/A | CF6: N/A | CG6: N/A | CH6: Sim | CI6: Tamper | CJ6: Face/Cartão/Senha | CK6: Simples ou combinado | CL6: Wiegand ou RS-485 | CM6: Sim | CN6: N/A | CO6: Sim | CP6: Sim | CQ6: Sim | CR6: Sim | CS6: Local (Wigand) e Global (Online) | CT6: Sim | CU6: Sim | CV6: Sim | CW6: Sim | CX6: Sim | CY6: PUSH SDK &BEST | CZ6: 1 | DA6: N/A | DB6: 1 | DC6: 1 | DD6: 2 (uma para entrada e outra pra saída) | DE6: 1 | DF6: 1 | DG6: 1 | DH6: 1 | DI6: 1 | DJ6: 1 | DK6: 1
A7: SpeedFace V3L Lite | B7: Descontinuado | C7: https://x.gd/P36FG | D7: https://x.gd/hr4vD | E7: https://x.gd/oB5oH | F7: https://x.gd/r3FYG | H7: https://x.gd/tzIpx | I7: https://x.gd/oOfK5 | J7: https://x.gd/3QcwW | L7: \\192.168.12.202\Zkteco\Documentos ZKTeco\06. Produtos\1. Controle de acesso de pessoas\1. Biométricos, RFID e QRCode\SpeedFace V3L (Lite) | M7: Z:\Documentos ZKTeco\06. Produtos\1. Controle de acesso de pessoas\1. Biométricos, RFID e QRCode\SpeedFace V3L (Lite)\Certificados | N7: 3.000 (Opcional: 10.000) | O7: 3000 | P7: N/A | Q7: N/A | R7: N/A | S7: 3.000 (Opcional: 10.000) | T7: 3.000 (Opcional: 10.000) | U7: 3.000 (Opcional: 10.000) | V7: 200000 | X7: 85437099 | Y7: Sim | Z7: TCP/IP (10/100Base-T) | AA7: sim | AB7: 12Vcc | AC7: 1.5A | AD7: ID 125Khz ou 13,56Mhz | AE7: 116,8 x 8,3 x 17,0 (mm) | AF7: 18W | AG7: -5°C a 45°C | AH7: 10% a 90% | AI7: IP65 | AJ7: N/A | AK7: 0.61 | AL7: Interno e externo | AM7: ISO 9001, ISO14001, CE, FCC, RoHS | AN7: 1. Equipamento montado. 2. Adesivo de posição de montagem e placa de montagem. 3. Guia rápido. 4. Fonte alimentação de 12V 3A. 5. Chave torx e parafusos de instalação. 6. Diodo FR107. | AO7: ZMM510 | AP7: ZMM510-NF24VC-Ver2.1.4 | AQ7: 1 GHz Dual Core | AR7: Linux embarcado | AS7: 256MB | AT7: 512MB | AU7: 2,4 Polegadas | AV7: Tela LCD IPS sensível ao toque | AW7: 240x320 | AX7: Camera Binocular 1MP | AY7: Autocompensação de LEDs IR e LEDs brancos. | AZ7: SPS1115G-03(1E-2P-35-1.0 30AWG 8Ω,1W,47.35×12.8mm,RoHS | BA7: (Sensitivity: -32dB / Omni-directional / Signal-to-Noise Ratio: 58dB / Impedance: 2.2kΩ) | BB7: N/A | BC7: N/A | BD7: 70.5 dB linear mode | BE7: Sonora (voz) e visual | BF7: 10/100Base-T | BG7: N/A | BH7: IEEE 802.11b / g / n 2.4GHz Wi-Fi 2,4 GHz ~ 2,4835 GHz Suporta 20 MHz e 40 MHz 64/128 bits WEP, WPA/WPA2, WPA-PSK/WPA2-PSK 802.11b: até 11 Mbps, 802.11g: até 54 Mbps, 802.11n: até 300 Mbps (HT40) | BI7: ZKBioCV Access e ZKBioCVSecurity | BJ7: TCP/IP | BK7: Sim | BL7: N/A | BM7: Privado (ZKBioCVSecurity ou ZKBioTalk) | BN7: N/A | BO7: N/A | BP7: Sim | BQ7: Luz visível | BR7: Algoritmo de inteligência artificial (IA) e reconhecimento facial vivo (liveness detection) para prevenir fraudes com fotos ou vídeos. | BS7: 3000 | BT7: N/A | BU7: N/A | BV7: 30cm a 120cm | BW7: ≤ 0.001% | BX7: ≤ 1% | BY7: <1s | BZ7: De 0 a 9 segundos | CA7: N/A | CB7: N/A | CC7: N/A | CD7: N/A | CE7: N/A | CF7: N/A | CG7: N/A | CH7: Sim | CI7: Tamper | CJ7: Face/Cartão/Senha | CK7: Simples ou combinado | CL7: N/A | CM7: Sim | CN7: Sim | CO7: Sim | CP7: Sim | CQ7: Sim | CR7: Senha | CS7: Global (Online) | CT7: N/A | CU7: N/A | CV7: Sim | CW7: Sim | CX7: Sim | CY7: PUSH SDK &BEST | CZ7: N/A | DA7: N/A | DB7: N/A | DC7: 1 | DD7: N/A | DE7: N/A | DF7: 1 | DG7: N/A | DH7: N/A | DI7: 1 | DJ7: 1 | DK7: 1
A8: FaceDepot 7BL | B8: Ativo | C8: https://x.gd/RsiME | D8: https://x.gd/3pALb | E8: https://x.gd/dphkr | F8: https://x.gd/TeNS4 | G8: https://x.gd/XKAqc | H8: https://x.gd/N9R41 | J8: https://x.gd/DUIn8 | K8: Não tem | L8: \\192.168.12.202\Zkteco\Documentos ZKTeco\06. Produtos\1. Controle de acesso de pessoas\1. Biométricos, RFID e QRCode\Facedepot 7BL | M8: Z:\Documentos ZKTeco\06. Produtos\1. Controle de acesso de pessoas\1. Biométricos, RFID e QRCode\Facedepot 7BL\Certificados | N8: 50000 | O8: 50.000 (Opcional: 100.000) | P8: Opcional:10.000 | Q8: Opcional:3.000 | R8: N/A | S8: Opcional:10.000 | T8: 50000 | U8: 50000 | V8: 200000 | X8: 85437099 | Y8: Sim | Z8: TCP/IP (10/100Base-T) | AA8: sim | AB8: 12Vcc | AC8: 3A | AD8: ID 125Khz ou 13,56Mhz | AE8: 91,93 x 202,93 x 21,5mm | AF8: 36W | AG8: 0°C a 45 °C | AH8: 20% a 80% | AI8: Opicional: IP65 (Apenas no FaceDepot 7BL-WP) | AJ8: N/A | AK8: 1.58 | AL8: Interno. Opcional: Externo | AM8: CE-RED,FCC | AN8: 1. Equipamento montado. 2. Adesivo de posição de montagem e placa de montagem. 3. Guia rápido. 4. Cabo de alimentação de 12 V/cabo RS232, RS485 /cabo RJ 45/cabo Wiegand/cabo de porta e sensor, etc. 5. Chave torx e parafusos de fixação. 6. Fonte de alimentação de 12V 3A. 7. Diodo FR107. | AO8: ZAM180 | AP8: ZAM180-NF70VA-Ver4.0.11 | AQ8: 900 MHz Dual Core | AR8: Linux embarcado | AS8: 1GB | AT8: 8GB | AU8: 7 Polegadas | AV8: Tela LCD IPS sensível ao toque | AW8: 720x1280 | AX8: Câmera 2MP Low Litght (WDR) | AY8: Autocompensação de LEDs IR e LEDs brancos. | AZ8: SQM0922LA008005J-R-03 8Ω¸ 1W 22*9*6.4mm(1E-2P-150-1.25 30AWG) IP67 | BA8: XDEC-EM4015-32dB-D140 Sensitivity-32dB±3dB 2.2KΩ φ4.0mm*1.5mm | BB8: Sensor óptico ZK | BC8: Z-ID | BD8: 81 dB linear mode 105 dB HDR mode | BE8: Sonora (voz) e visual | BF8: 10/100Base-T | BG8: N/A | BH8: IEEE 802.11b / g / n 2.4GHz Wi-Fi 2,4 GHz ~ 2,4835 GHz Suporta 20 MHz e 40 MHz 64/128 bits WEP, WPA/WPA2, WPA-PSK/WPA2-PSK 802.11b: até 11 Mbps, 802.11g: até 54 Mbps, 802.11n: até 300 Mbps (HT40) | BI8: ZKBioCV Access e ZKBioCVSecurity | BJ8: TCP/IP | BK8: Sim | BL8: OSDP V2.1.7 | BM8: N/A | BN8: N/A | BO8: N/A | BP8: Sim | BQ8: Luz visível | BR8: Algoritmo de inteligência artificial (IA) e reconhecimento facial vivo (liveness detection) para prevenir fraudes com fotos ou vídeos. | BS8: 3000 | BT8: Sim | BU8: N/A | BV8: 30cm a 200cm | BW8: ≤ 0.01% | BX8: ≤ 0.02% | BY8: <1s | BZ8: De 0 a 9 segundos | CA8: ≤ 0.0001% | CB8: ≤ 0.01% | CC8: <0.3s | CD8: Até 50cm | CE8: ≤ 0.05% | CF8: ≤ 1.8% | CG8: <0.35s | CH8: Sim | CI8: Tamper | CJ8: Face/Senha (Opcional: Digital/Cartão/Palma | CK8: Simples ou combinado | CL8: Wiegand ou RS-485 | CM8: Sim | CN8: N/A | CO8: Sim | CP8: Sim | CQ8: Sim | CR8: Impressão digital ou senha | CS8: Local (Wigand) e Global (Online) | CT8: Sim | CU8: Sim | CV8: Sim | CW8: Sim | CX8: Sim | CY8: PUSH SDK | CZ8: 1 | DA8: 2 | DB8: 2 | DC8: N/A | DD8: 2 (uma para entrada e outra pra saída) | DE8: 1 | DF8: 1 | DG8: 1 | DH8: 1 | DI8: 1 | DJ8: 1 | DK8: 1
A9: ProMA | B9: Não comercializado | C9: https://x.gd/dUU6Q | D9: https://x.gd/hN3J9 | E9: https://x.gd/d5M177 | F9: https://x.gd/f9n6w | M9: \\192.168.12.202\Zkteco\Documentos ZKTeco\06. Produtos\1. Controle de acesso de pessoas\1. Biométricos, RFID e QRCode\ProMA | N9: 30000 | O9: 30000 | P9: 10000 | Q9: Opcional: 5.000 | R9: N/A | S9: N/A | T9: 30000 | U9: 30000 | V9: 500000 | X9: 85437099 | Y9: Sim | Z9: TCP/IP (10/100Base-T) | AA9: sim | AB9: 12Vcc | AC9: 3A | AD9: ID 125Khz ou 13,56Mhz | AE9: 68,7 x 194,7 x 28,3mm | AF9: 36W | AG9: -26°C a 55 °C | AH9: ≤ 93% | AI9: IP66 | AJ9: IK07 | AK9: 1.41 | AL9: Interno e externo | AM9: CE-RED,FCC | AN9: 1. Equipamento montado. 2. Adesivo de posição de montagem e placa de montagem. 3. Guia rápido. 4. Fonte de alimentação de 12V 3A. 5. Chave torx e parafusos de fixação. 6. Diodo FR107. | AO9: ZAM180 | AP9: ZAM180-NF20VA-Ver4.0.7 | AQ9: 1 GHz Quad Core | AR9: Linux embarcado | AS9: 1GB | AT9: 8GB | AU9: 2 Polegadas | AV9: Tela TFT | AW9: 240x320 | AX9: Camera Binocular 2MP | AY9: Autocompensação de LEDs IR e LEDs brancos. | AZ9: XDEC-2415B08J20NF26-D20,8Ω,1W,24×15×5mm(1E-2P-20-1.25 32AWG),RoHS | BA9: XDEC-EM4015 -32dB-D60 Sensitivity-32dB±3dB 2.2KΩ,φ4.0mm*1.5mm (1E-2P-40-1.25,60mm±5mm) RoHS | BB9: Sensor óptico ZK | BC9: Z-ID | BD9: Sim (WDRStatus=1) (81 dB linear mode 105 dB HDR mode) | BE9: Sonora (voz) e visual | BF9: 10/100Base-T | BG9: PoE IEEE 802.3af / at (externo) | BH9: Não | BI9: ZKBioCV Access e ZKBioCVSecurity | BJ9: TCP/IP | BK9: Sim | BL9: N/A | BM9: Privado (ZKBioCVSecurity ou ZKBioTalk) | BN9: Sim (Profile S???? | BO9: Sim | BP9: Sim | BQ9: Luz visível | BR9: Algoritmo de inteligência artificial (IA) e reconhecimento facial vivo (liveness detection) para prevenir fraudes com fotos ou vídeos. | BS9: 30000 | BT9: Sim | BU9: N/A | BV9: 30cm a 200cm | BW9: ≤ 0.01% | BX9: ≤ 0.02% | BY9: ≤0,3s | BZ9: De 0 a 9 segundos | CA9: ≤ 0.0001% | CB9: ≤ 0.01% | CC9: <0.3s | CD9: Até 50cm | CE9: ≤ 0.05% | CF9: ≤ 1.8% | CG9: <0.35s | CH9: Sim | CI9: Rede TCP/IP (SSH) | CJ9: Face/ Digital (Opcional: Palma) | CK9: Simples ou combinado | CL9: Wiegand ou RS-485 | CM9: Sim | CN9: Sim | CO9: Sim | CP9: Sim | CQ9: Sim | CR9: Apenas no ProMA | CS9: Local (Wigand) e Global (Online) | CT9: Sim | CU9: Sim | CV9: Sim | CW9: Sim | CX9: Sim | CY9: PUSH SDK | CZ9: 1 | DA9: N/A | DB9: 1 | DC9: 1 | DD9: 2 (uma para entrada e outra pra saída) | DE9: N/A | DF9: 1 | DG9: 1 | DH9: 1 | DI9: 1 | DJ9: 1 | DK9: 1
A10: ProMA-QR | B10: Ativo | C10: https://x.gd/GzN3O | D10: https://x.gd/AxN2g | E10: https://x.gd/I6pbP | F10: https://x.gd/QWTKH | G10: https://x.gd/aPl5G | H10: https://x.gd/NNLc4 | J10: https://x.gd/RIkCo | L10: \\192.168.12.202\Zkteco\Documentos ZKTeco\06. Produtos\1. Controle de acesso de pessoas\1. Biométricos, RFID e QRCode\ProMA | M10: \\192.168.12.202\Zkteco\Documentos ZKTeco\06. Produtos\1. Controle de acesso de pessoas\1. Biométricos, RFID e QRCode\ProMA | N10: 30000 | O10: 30.000 (Opcional: 50.000) | P10: N/A | Q10: Opcional: 5.000 | R10: 100000 | S10: N/A | T10: 30000 | U10: 30000 | V10: 500000 | X10: 85437099 | Y10: Sim | Z10: TCP/IP (10/100Base-T) | AA10: sim | AB10: 12Vcc | AC10: 3A | AD10: ID 125Khz ou 13,56Mhz | AE10: 68,7 x 194,7 x 28,3mm | AF10: 36W | AG10: -26°C a 55 °C | AH10: ≤ 93% | AI10: IP66 | AJ10: IK07 | AK10: 1.41 | AL10: Interno e externo | AM10: CE-RED,FCC | AN10: 1. Equipamento montado. 2. Adesivo de posição de montagem e placa de montagem. 3. Guia rápido 4. Fonte de alimentação de 12V 3A. 5. Chave torx e parafusos de fixação. 6. Diodo FR107. | AO10: ZAM180 | AP10: ZAM180-NF20VA-Ver4.0.7 | AQ10: 1 GHz Quad Core | AR10: Linux embarcado | AS10: 1GB | AT10: 8GB | AU10: 2 Polegadas | AV10: Tela TFT | AW10: 240x320 | AX10: Camera Binocular 2MP | AY10: Autocompensação de LEDs IR e LEDs brancos. | AZ10: XDEC-2415B08J20NF26-D20,8Ω,1W,24×15×5mm(1E-2P-20-1.25 32AWG),RoHS | BA10: XDEC-EM4015 -32dB-D60 Sensitivity-32dB±3dB 2.2KΩ,φ4.0mm*1.5mm (1E-2P-40-1.25,60mm±5mm) RoHS | BB10: N/A | BC10: N/A | BD10: Sim (WDRStatus=1) | BE10: Sonora (voz) e visual | BF10: 10/100Base-T | BG10: PoE IEEE 802.3af / at (externo) | BH10: Não | BI10: ZKBioCV Access e ZKBioCVSecurity | BJ10: TCP/IP | BK10: Sim | BL10: N/A | BM10: Privado (ZKBioCVSecurity ou ZKBioTalk) | BN10: Sim (Profile S???? | BO10: Sim | BP10: Sim | BQ10: Luz visível | BR10: Algoritmo de inteligência artificial (IA) e reconhecimento facial vivo (liveness detection) para prevenir fraudes com fotos ou vídeos. | BS10: 30000 | BT10: Sim | BU10: N/A | BV10: 30cm a 200cm | BW10: ≤ 0.01% | BX10: ≤ 0.02% | BY10: ≤0,3s | BZ10: De 0 a 9 segundos | CA10: N/A | CB10: N/A | CC10: N/A | CD10: Até 50cm | CE10: ≤ 0.05% | CF10: ≤ 1.8% | CG10: <0.35s | CH10: Sim | CI10: Rede TCP/IP (SSH) | CJ10: Face/QR Code (Opcional: Palma) | CK10: Simples ou combinado | CL10: Wiegand ou RS-485 | CM10: Sim | CN10: Sim | CO10: Sim | CP10: Sim | CQ10: Sim | CR10: Apenas no ProMA | CS10: Local (Wigand) e Global (Online) | CT10: Sim | CU10: Sim | CV10: Sim | CW10: Sim | CX10: Sim | CY10: PUSH SDK | CZ10: 1 | DA10: N/A | DB10: 1 | DC10: 1 | DD10: 2 (uma para entrada e outra pra saída) | DE10: N/A | DF10: 1 | DG10: 1 | DH10: 1 | DI10: 1 | DJ10: 1 | DK10: 1
A11: ProMA-RF | B11: Não comercializado | C11: https://x.gd/CyiTH | D11: https://x.gd/lseLK | E11: https://x.gd/c3pAX | F11: https://x.gd/mseG6 | M11: \\192.168.12.202\Zkteco\Documentos ZKTeco\06. Produtos\1. Controle de acesso de pessoas\1. Biométricos, RFID e QRCode\ProMA | N11: 30000 | O11: N/A | P11: N/A | Q11: Opcional: 5.000 | R11: Opcional: 5.000 | S11: 100000 | V11: 500000 | X11: 85437099 | Y11: Sim | Z11: TCP/IP (10/100Base-T) | AA11: sim | AB11: 12Vcc | AC11: 3A | AD11: ID 125Khz ou 13,56Mhz | AE11: 68,7 x 194,7 x 28,3mm | AF11: 36W | AG11: -26°C a 55 °C | AH11: ≤ 93% | AI11: IP66 | AJ11: IK07 | AK11: 1.41 | AL11: Interno e externo | AM11: CE-RED,FCC | AN11: 1. Equipamento montado. 2. Adesivo de posição de montagem e placa de montagem. 3. Guia rápido. 4. Fonte de alimentação de 12V 3A. 5. Chave torx e parafusos de fixação. 6. Diodo FR107. | AO11: ZAM180 | AP11: ZAM180-NF20VA-Ver4.0.7 | AQ11: 1 GHz Quad Core | AR11: Linux embarcado | AS11: 1GB | AT11: 8GB | AU11: 2 Polegadas | AV11: Tela TFT | AW11: 240x320 | AX11: Camera Binocular 2MP | AY11: Autocompensação de LEDs IR e LEDs brancos. | AZ11: XDEC-2415B08J20NF26-D20,8Ω,1W,24×15×5mm(1E-2P-20-1.25 32AWG),RoHS | BA11: XDEC-EM4015 -32dB-D60 Sensitivity-32dB±3dB 2.2KΩ,φ4.0mm*1.5mm (1E-2P-40-1.25,60mm±5mm) RoHS | BB11: N/A | BC11: N/A | BD11: Sim (WDRStatus=1) | BE11: Sonora (voz) e visual | BF11: 10/100Base-T | BG11: PoE IEEE 802.3af / at (externo) | BH11: Não | BI11: ZKBioCV Access e ZKBioCVSecurity | BJ11: TCP/IP | BK11: Sim | BL11: N/A | BM11: Privado (ZKBioCVSecurity ou ZKBioTalk) | BN11: Sim (Profile S???? | BO11: Sim | BP11: Sim | BQ11: Luz visível | BR11: Algoritmo de inteligência artificial (IA) e reconhecimento facial vivo (liveness detection) para prevenir fraudes com fotos ou vídeos. | BS11: 30000 | BT11: Sim | BU11: N/A | BV11: 30cm a 200cm | BW11: ≤ 0.01% | BX11: ≤ 0.02% | BY11: ≤0,3s | BZ11: De 0 a 9 segundos | CA11: N/A | CB11: N/A | CC11: N/A | CD11: Até 50cm | CE11: ≤ 0.05% | CF11: ≤ 1.8% | CG11: <0.35s | CH11: Sim | CI11: Rede TCP/IP (SSH) | CJ11: Face/QR Code (Opcional: Palma) | CK11: Simples ou combinado | CL11: Wiegand ou RS-485 | CM11: Sim | CN11: Sim | CO11: Sim | CP11: Sim | CQ11: Sim | CR11: Apenas no ProMA | CS11: Local (Wigand) e Global (Online) | CT11: Sim | CU11: Sim | CV11: Sim | CW11: Sim | CX11: Sim | CY11: PUSH SDK | CZ11: 1 | DA11: N/A | DB11: 1 | DC11: 1 | DD11: 2 (uma para entrada e outra pra saída) | DE11: N/A | DF11: 1 | DG11: 1 | DH11: 1 | DI11: 1 | DJ11: 1 | DK11: 1
A12: Proface X [P] | B12: Ativo | C12: https://x.gd/dfTkm | D12: https://x.gd/yvtVL | E12: https://x.gd/sLOJQ | F12: https://x.gd/l8RJO | G12: https://x.gd/iZgpR | J12: https://x.gd/AlM2U | L12: \\192.168.12.202\Zkteco\Documentos ZKTeco\06. Produtos\1. Controle de acesso de pessoas\1. Biométricos, RFID e QRCode\ProFace X[P] | M12: Z:\Documentos ZKTeco\06. Produtos\1. Controle de acesso de pessoas\1. Biométricos, RFID e QRCode\ProFace X - ZAM 180\Certificados | N12: 50000 | O12: 50.000 (Opcional: 100.000) | P12: N/A | Q12: 5000 | R12: 50000 | S12: 50000 | T12: 50000 | U12: 50000 | V12: 1.000.000 (Opcional: 2.000.000) | X12: 85437099 | Y12: Sim | Z12: TCP/IP (10/100Base-T) | AA12: sim | AB12: 12Vcc | AC12: 3A | AD12: ID 125Khz ou 13,56Mhz | AE12: 227 x 143 x 26 mm | AF12: 36W | AG12: -30°C a 60°C | AH12: ≤ 93% | AI12: IP68 | AJ12: IK04 (Opcional: IK10) | AK12: 2 | AL12: Interno e externo | AM12: ISO14001, ISO9001, CE, FCC, RoHS | AN12: 1. Equipamento montado. 2. Adesivo de posição de montagem e placa de montagem. 3. Guia rápido. 4. Fonte de alimentação de 12V 3A. 5. Chave torx e parafusos de fixação. 6. Diodo FR107. | AO12: ZAM-180 | AP12: ZAM180-NF80VC-Ver3.3.4 | AQ12: 1 GHz Dual Core | AR12: Linux embarcado | AS12: 1GB | AT12: 8GB | AU12: 8 polegadas | AV12: Tela LCD IPS (400lux) sensível ao toque | AW12: 800x1280 | AX12: Câmera 2MP Low Litght (WDR) | AY12: Autocompensação de LEDs IR e LEDs brancos. | AZ12: Left Spaker:SQM0922LA008005J-R-03 8Ω¸ 1W 22*9*6.4mm(1E-2P-150-1.25 30AWG) IP67 Right Spaker:SQW2209XJ08-001 8Ω1W 22*9*6mm(1E-2P-35-1.25 30AWG) IP67 | BA12: XDEC-EM4015-32dB-D90 -32dB±3dB 2.2KΩ,φ4.0mm*1.5mm (1E-2P-90-1.25 ,90mm±0.5mm) | BB12: N/A | BC12: N/A | BD12: 81 dB linear mode 105 dB HDR mode | BE12: Sonora (voz) e visual | BF12: 10/100Base-T | BG12: Não | BH12: Opcional | BI12: ZKBioCV Access e ZKBioCVSecurity | BJ12: TCP/IP | BK12: Sim | BL12: N/A | BM12: Privado (ZKBioCVSecurity ou ZKBioTalk) | BN12: Sim (Profile S???? | BO12: Sim | BP12: Sim | BQ12: Luz visível | BR12: Algoritmo de inteligência artificial (IA) e reconhecimento facial vivo (liveness detection) para prevenir fraudes com fotos ou vídeos. | BS12: 50000 | BT12: Sim | BU12: Sim | BV12: 30cm a 200cm | BW12: ≤ 0.01% | BX12: ≤ 0.02% | BY12: 0,3s | BZ12: De 0 a 9 segundos | CA12: N/A | CB12: N/A | CC12: N/A | CD12: Até 50cm | CE12: ≤ 0.05% | CF12: ≤ 1.8% | CG12: <0.35s | CH12: Sim | CI12: Tamper | CJ12: Face/Palma/Cartão/QR Code/Senha | CK12: Simples ou combinado | CL12: Wiegand ou RS-485 | CM12: Sim | CN12: Sim | CO12: Sim | CP12: Sim | CQ12: Sim | CR12: Por senha | CS12: Local (Wigand) e Global (Online) | CT12: Sim | CU12: Sim | CV12: Sim | CW12: Sim | CX12: Sim | CY12: PUSH SDK | CZ12: 1 | DA12: 1 | DB12: 3 | DC12: N/A | DD12: 2 (uma para entrada e outra pra saída) | DE12: N/A | DF12: 1 | DG12: 1 | DH12: 1 | DI12: 1 | DJ12: 1 | DK12: 1
A13: Proface X [SL] | B13: Ativo | C13: https://x.gd/7kv9n | D13: https://x.gd/lZ6KH | G13: https://x.gd/UcXGg | H13: https://x.gd/7ZECc | I13: https://x.gd/IWRjf | J13: https://x.gd/IgZap | L13: \\192.168.12.202\Zkteco\Documentos ZKTeco\06. Produtos\1. Controle de acesso de pessoas\1. Biométricos, RFID e QRCode\Proface X (SL) | M13: Não temos essa informação | N13: 50000 | O13: 30.000 (Opcional: 50.000) | P13: N/A | Q13: N/A | R13: N/A | S13: 50000 | T13: 50000 | U13: 50000 | V13: 1.000.000 (Opcional: 2.000.000) | X13: 85437099 | Y13: Sim | Z13: TCP/IP (10/100Base-T) | AA13: sim | AB13: 12Vcc | AC13: 3A | AD13: 13,56Mhz | AE13: 227 x 143 x 26 mm | AF13: 36W | AG13: -30°C a 60°C | AH13: ≤ 93% | AI13: IP68 | AJ13: IK04 | AK13: 2 | AL13: Interno (devido a tecnologia de luz struturada 3D) | AM13: Não tem | AN13: 1. Equipamento montado 2. Adesivo de posição de montagem e placa de montagem. 3. Guia rápido. 4. Fonte de alimentação de 12V 3A. 5. Chave torx e parafusos de fixação. 6. Diodo FR107. | AO13: ZAM170 | AP13: 3.0.36 | AQ13: 900MHz Dual Core | AR13: Linux embarcado | AS13: 1GB | AT13: 8GB | AU13: 8 polegadas | AV13: Tela LCD IPS sensível ao toque | AW13: 800x1280 | AX13: Câmera 2MP Low Litght (WDR) | AY13: Autocompensação de LEDs IR e LEDs brancos. | AZ13: Left Spaker:SQM0922LA008005J-R-03 8Ω¸ 1W 22*9*6.4mm(1E-2P-150-1.25 30AWG) IP67 Right Spaker:SQW2209XJ08-001 8Ω1W 22*9*6mm(1E-2P-35-1.25 30AWG) IP67 | BA13: N/A | BB13: N/A | BC13: N/A | BD13: 81 dB linear mode 105 dB HDR mode | BE13: Sonora (voz) e visual | BF13: 10/100Base-T | BG13: Não | BH13: Opcional | BI13: ZKBioCV Access e ZKBioCVSecurity | BJ13: TCP/IP | BK13: Sim | BL13: N/A | BM13: Privado (ZKBioCVSecurity ou ZKBioTalk) | BN13: N/A | BO13: N/A | BP13: Sim | BQ13: Luz struturada 3D | BR13: Algoritmo de inteligência artificial (IA) e reconhecimento facial vivo (liveness detection) para prevenir fraudes com fotos ou vídeos. | BS13: 40000 | BT13: Sim | BU13: N/A | BW13: ≤ 0.01% | BX13: ≤ 0.02% | BY13: 0,3s | BZ13: De 0 a 9 segundos | CA13: N/A | CB13: N/A | CC13: N/A | CD13: N/A | CE13: N/A | CF13: N/A | CG13: N/A | CH13: Sim | CI13: Tamper | CJ13: Face/Cartão/Senha | CK13: Simples ou combinado | CL13: Wiegand ou RS-485 | CM13: Sim | CN13: Sim | CO13: Sim | CP13: Sim | CQ13: Sim | CR13: Senha | CS13: Local (Wigand) e Global (Online) | CT13: Sim | CU13: Sim | CV13: Sim | CW13: Sim | CX13: Sim | CY13: PUSH SDK | CZ13: 1 | DA13: 1 | DB13: 3 | DC13: N/A | DD13: 2 (uma para entrada e outra pra saída) | DE13: N/A | DF13: 1 | DG13: 1 | DH13: 1 | DI13: 1 | DJ13: 1 | DK13: 1
A14: Proface X [DS] | B14: Ativo | C14: https://x.gd/qhlEE | D14: https://x.gd/NHkVf | E14: https://x.gd/SGZhM | F14: https://x.gd/VpgLO | G14: https://x.gd/96yRQ | H14: https://x.gd/3SJEA | J14: https://x.gd/P9rWl | L14: Z:\Documentos ZKTeco\06. Produtos\1. Controle de acesso de pessoas\1. Biométricos, RFID e QRCode\ProFace X DS | M14: Z:\Documentos ZKTeco\06. Produtos\1. Controle de acesso de pessoas\1. Biométricos, RFID e QRCode\ProFace X DS\Certificados | N14: 50000 | O14: 30.000 (Opcional: 50.000) | P14: N/A | Q14: N/A | R14: 50000 | S14: 50000 | T14: 50000 | U14: 50000 | V14: 1.000.000 (Opcional: 2.000.000) | X14: 85437099 | Y14: Sim | Z14: TCP/IP (10/100Base-T) | AA14: sim | AB14: 12Vcc | AC14: 3A | AD14: ID 125Khz ou 13,56Mhz | AE14: 227 x 143 x 26 mm | AF14: 36W | AG14: -20°C a 55°C | AH14: ≤ 93% | AI14: IP68 | AJ14: IK04 | AK14: 2 | AL14: Interno e externo | AM14: CE-RED,FCC | AN14: 1. Equipamento montado. 2. Adesivo de posição de montagem e placa de montagem. 3. Guia rápido. 4. Fonte de alimentação de 12V 3A. 5. Chave torx e parafusos de fixação. 6. Diodo FR107 | AO14: ZAM200 | AP14: ZAM200-NF80VF-Ver8.0.2 | AQ14: 1.2 GHz Quad-core | AR14: Linux embarcado | AS14: 1GB | AT14: 8GB | AU14: 8 polegadas | AV14: Tela LCD sensível ao toque | AW14: 800x1280 | AX14: Câmera 2MP Low Litght (WDR) | AY14: Autocompensação de LEDs IR e LEDs brancos. | AZ14: Left Spaker:SQM0922LA008005J-R-03 8Ω¸ 1W 22*9*6.4mm(1E-2P-150-1.25 30AWG) IP67 Right Spaker:SQW2209XJ08-001 8Ω1W 22*9*6mm(1E-2P-35-1.25 30AWG) IP67 | BA14: XDEC-EM4015-32dB-D90 -32dB±3dB 2.2KΩ,φ4.0mm*1.5mm (1E-2P-90-1.25 ,90mm±0.5mm) | BB14: N/A | BC14: N/A | BD14: 81 dB linear mode 105 dB HDR mode | BE14: Sonora (voz) e visual | BF14: 10/100Base-T | BG14: Não | BH14: Opcional | BI14: ZKBioCV Access e ZKBioCVSecurity | BJ14: TCP/IP | BK14: Sim | BL14: N/A | BM14: Privado (ZKBioCVSecurity ou ZKBioTalk) | BN14: N/A | BO14: N/A | BP14: Sim | BQ14: Dual Spectrum (Luz visível + IR) | BR14: Algoritmo de inteligência artificial (IA) e reconhecimento facial vivo (liveness detection) para prevenir fraudes com fotos ou vídeos. | BS14: 100000 | BT14: Sim | BU14: N/A | BV14: 30cm a 200cm | BW14: ≤ 0.01% | BX14: ≤ 0.02% | BY14: 0,3s | BZ14: De 0 a 9 segundos | CA14: N/A | CB14: N/A | CC14: N/A | CD14: N/A | CE14: N/A | CF14: N/A | CG14: N/A | CH14: Sim | CI14: Tamper | CJ14: Face/Cartão/QR Code/Senha | CK14: Simples ou combinado | CL14: Wiegand ou RS-485 | CM14: Sim | CN14: Sim | CO14: Sim | CP14: Sim | CQ14: Sim | CR14: Senha | CS14: Local (Wigand) e Global (Online) | CT14: Sim | CU14: Sim | CV14: Sim | CW14: Sim | CX14: Sim | CY14: PUSH SDK | CZ14: 1 | DA14: 1 | DB14: 3 | DC14: N/A | DD14: 2 (uma para entrada e outra pra saída) | DE14: N/A | DF14: 1 | DG14: 1 | DH14: 1 | DI14: 1 | DJ14: 1 | DK14: 1
A15: SenseFace 7A | B15: Ativo | C15: https://x.gd/k4Zlp | D15: https://x.gd/WU2sm | E15: https://x.gd/KNYpG | F15: https://x.gd/sNoYY | G15: https://x.gd/OFIDL | H15: https://x.gd/xPQo7 | L15: \\192.168.12.202\Zkteco\Documentos ZKTeco\06. Produtos\1. Controle de acesso de pessoas\1. Biométricos, RFID e QRCode\SenseFace\SenseFace 7A | M15: Z:\Documentos ZKTeco\06. Produtos\1. Controle de acesso de pessoas\1. Biométricos, RFID e QRCode\SenseFace\Certificações\Certificações (China) | N15: 10.000 (Opcional: 50.000) | O15: 10.000 (Opcional: 50.000) | P15: 10.000 (Opcional: 50.000) | Q15: N/A | R15: N/A | S15: Em breve | T15: 10.000 (Opcional: 50.000) | U15: 10.000 (Opcional: 50.000) | V15: 300000 | X15: 85437099 | Y15: Sim | Z15: TCP/IP (10/100Base-T) | AA15: Não | AB15: 12Vcc | AC15: 3A | AD15: 13,56Mhz | AE15: 238 x 115 x 22,3mm | AF15: 36W | AG15: -5°C a 45°C | AH15: 10% a 90% | AI15: IP65 | AJ15: N/A | AK15: 0.622 | AL15: Interno e externo | AM15: ISO14001, ISO9001, CE, FCC, RoHS | AN15: 1. Equipamento montado. 2. Adesivo de posição de montagem e placa de montagem. 3. Guia rápido 4. Cabo de alimentação de 12 V/cabo RS232, RS485 /cabo RJ 45/cabo Wiegand/cabo de porta e sensor, etc. 5. Chave torx e parafusos de fixação. 6. Diodo FR107 | AO15: ZAM70 | AP15: ZAM70-NF70VA-Ver3.0.15 | AQ15: 1 GHz Dual Core | AR15: Linux embarcado | AS15: 512MB | AT15: 8GB | AU15: 7 polegadas | AV15: Tela LED sensível ao toque TFT colorida | AW15: 600*1024 | AX15: Camera Binocular 1MP (WDR) | AY15: Autocompensação de LEDs IR | AZ15: 8ohm @1W | BA15: Sensitivity: -32dB / Omni-directional / Signal-to-Noise Ratio: -32dB / Impedance: 2.2kΩ) | BB15: Sensor óptico ZK (in glass) | BC15: Z-ID | BD15: 83 dB linear mode | BE15: Sonora (voz) e visual | BF15: 10/100Base-T | BG15: Não | BH15: Sim | BI15: ZKBioCV Access e ZKBioCVSecurity | BJ15: TCP/IP | BK15: Sim | BL15: N/A | BM15: Público (Proprietário) e Privado | BN15: Sim (Compatível com Perfil S, Perfil T, Perfil G, Perfil C, Perfil Q e Perfil A) | BO15: Sim | BP15: Sim | BQ15: Luz visível | BR15: Algoritmo de inteligência artificial (IA) e reconhecimento facial vivo (liveness detection) para prevenir fraudes com fotos ou vídeos. | BS15: 100000 | BT15: Sim | BU15: N/A | BV15: 30cm to 200cm | BW15: ≤ 0.01% | BX15: ≤ 0.02% | BY15: 0,35s | BZ15: De 0 a 9 segundos | CA15: ≤ 0.0001% | CB15: ≤ 0.01% | CC15: < 0.5 s | CD15: N/A | CE15: N/A | CF15: N/A | CG15: N/A | CH15: Sim | CI15: Tamper | CJ15: Face/Impressão digital/Cartão/Senha | CK15: Simples ou combinado | CL15: Wiegand ou RS-485 | CM15: Sim | CN15: Não | CO15: Sim | CP15: Sim | CQ15: Sim | CR15: Impressão digital ou senha | CS15: Local (Wigand) e Global (Online) | CT15: Sim | CU15: Não | CV15: Sim | CW15: Sim | CX15: Sim | CY15: PUSH SDK e BEST | CZ15: 1 | DA15: N/A | DB15: 1 | DC15: N/A | DD15: 1 (saída ou entrada) | DE15: 1 | DF15: 1 | DG15: 1 | DH15: N/A | DI15: 1 | DJ15: 1 | DK15: 1 | DM15: Sim
A16: SenseFace 4A | B16: Ativo | C16: https://x.gd/JYIS6 | D16: https://x.gd/kGDgP | E16: https://x.gd/schbV | F16: https://x.gd/r1SY5 | G16: https://x.gd/FhhgH | H16: https://x.gd/Ub2rS | L16: Z:\Documentos ZKTeco\06. Produtos\1. Controle de acesso de pessoas\1. Biométricos, RFID e QRCode\SenseFace\SenseFace 4A | M16: Z:\Documentos ZKTeco\06. Produtos\1. Controle de acesso de pessoas\1. Biométricos, RFID e QRCode\SenseFace\Certificações\Certificações (China) | N16: 8000 | O16: 6000 | P16: 8000 | Q16: N/A | R16: N/A | S16: Em breve | T16: 8000 | U16: 8000 | V16: 200000 | X16: 85437099 | Y16: Sim | Z16: TCP/IP (10/100Base-T) | AA16: Não | AB16: 12Vcc | AC16: 3A | AD16: N/A | AE16: 175.00 x 84.50 x 21.65 mm | AF16: 36W | AG16: -5°C a 45°C | AH16: 10% a 90% | AI16: IP65 | AJ16: N/A | AK16: 0.264 | AL16: Interno e externo | AM16: ISO14001, ISO9001, CE, FCC, RoHS | AN16: 1. Equipamento montado. 2. Adesivo de posição de montagem e placa de montagem. 3. Guia rápido 4. Cabo de alimentação de 12 V/cabo RS232, RS485 /cabo RJ 45/cabo Wiegand/cabo de porta e sensor, etc. 5. Chave torx e parafusos de fixação. 6. Diodo FR107 | AO16: ZAM70 | AP16: ZAM70-NF70VA-Ver3.0.15 | AQ16: 1 GHz Dual Core | AR16: Linux embarcado | AS16: 512MB | AT16: 8GB | AU16: 4,3 polegadas | AV16: Tela LED sensível ao toque TFT colorida | AW16: 272*480 | AX16: Camera Binocular 1MP (WDR) | AY16: Autocompensação de LEDs IR | AZ16: 8ohm @1W | BA16: Sensitivity: -42 dB/ Omni-directional/ Signal-to-Noise Ratio: 58 dB/ Impedance: 2.2kΩ) | BB16: Sensor óptico ZK (in glass) | BC16: Z-ID | BD16: 83 dB linear mode | BE16: Sonora (voz) e visual | BF16: 10/100Base-T | BG16: Não | BH16: Sim | BI16: ZKBioCV Access e ZKBioCVSecurity | BJ16: TCP/IP | BK16: Sim | BL16: N/A | BM16: Público (Proprietário) e Privado | BN16: Sim (Compatível com Perfil S, Perfil T, Perfil G, Perfil C, Perfil Q e Perfil A) | BO16: Sim | BP16: Sim | BQ16: Luz visível | BR16: Algoritmo de inteligência artificial (IA) e reconhecimento facial vivo (liveness detection) para prevenir fraudes com fotos ou vídeos. | BS16: 100000 | BT16: Sim | BU16: N/A | BV16: 30cm a 200cm | BW16: ≤ 0.01% | BX16: ≤ 0.02% | BY16: 0,35s | BZ16: De 0 a 9 segundos | CA16: ≤ 0.0001% | CB16: ≤ 0.01% | CC16: < 0.5 s | CD16: N/A | CE16: N/A | CF16: N/A | CG16: N/A | CH16: Sim | CI16: Tamper | CJ16: Face/Impressão digital/Cartão/Senha | CK16: Simples ou combinado | CL16: Wiegand ou RS-485 | CM16: Sim | CN16: Não | CO16: Sim | CP16: Sim | CQ16: Sim | CR16: Impressão digital ou senha | CS16: Local (Wigand) e Global (Online) | CT16: Sim | CU16: Não | CV16: Sim | CW16: Sim | CX16: Sim | CY16: PUSH SDK e BEST | CZ16: 1 | DA16: N/A | DB16: 1 | DC16: N/A | DD16: 1 (saída ou entrada) | DE16: 1 | DF16: 1 | DG16: 1 | DH16: N/A | DI16: 1 | DJ16: 1 | DK16: 1 | DM16: Sim
